<?xml version="1.0" encoding="utf-8"?><testsuites><testsuite errors="0" failures="6" hostname="NOTEBOOK19" name="pytest" skipped="3" tests="20" time="3.075" timestamp="2020-02-11T17:24:25.495199"><testcase classname="test_addition" file="test_addition.py" line="1" name="test_add[5-5-10]" time="0.002"></testcase><testcase classname="test_addition" file="test_addition.py" line="1" name="test_add[3-5-12]" time="0.002"><failure message="AssertionError: failed
assert 8 == 12
  -8
  +12">input1 = 3, input2 = 5, output = 12

    @pytest.mark.parametrize(&quot;input1, input2, output&quot;,[(5,5,10),(3,5,12)])
    def test_add(input1, input2, output):
&gt;   	assert input1+input2 == output,&quot;failed&quot;
E    AssertionError: failed
E    assert 8 == 12
E      -8
E      +12

test_addition.py:4: AssertionError</failure></testcase><testcase classname="test_addition2" file="test_addition2.py" line="1" name="test_add_1" time="0.000"><skipped message="unconditional skip" type="pytest.skip">test_addition2.py:2: unconditional skip</skipped></testcase><testcase classname="test_addition2" file="test_addition2.py" line="5" name="test_add_2" time="0.002"><skipped message="unconditional skip" type="pytest.skip">test_addition2.py:6: unconditional skip</skipped></testcase><testcase classname="test_addition2" file="test_addition2.py" line="9" name="test_add_3" time="0.002"></testcase><testcase classname="test_addition2" file="test_addition2.py" line="13" name="test_add_4" time="0.002"><skipped message="" type="pytest.xfail"></skipped></testcase><testcase classname="test_addition2" file="test_addition2.py" line="17" name="test_add_5" time="0.002"></testcase><testcase classname="test_addition2" file="test_addition2.py" line="20" name="test_add_6" time="0.002"><failure message="AssertionError: failed
assert 5 == 6
  -5
  +6">def test_add_6():
&gt;   	assert 3+2 == 6,&quot;failed&quot;
E    AssertionError: failed
E    assert 5 == 6
E      -5
E      +6

test_addition2.py:22: AssertionError</failure></testcase><testcase classname="test_basic_fixture" file="test_basic_fixture.py" line="8" name="test_comparewithAA" time="0.004"><failure message="AssertionError: aa and zz comparison failed
assert 25 == 35
  -25
  +35">supply_AA_BB_CC = [25, 35, 45]

    def test_comparewithAA(supply_AA_BB_CC):
    	zz=35
&gt;   	assert supply_AA_BB_CC[0]==zz,&quot;aa and zz comparison failed&quot;
E    AssertionError: aa and zz comparison failed
E    assert 25 == 35
E      -25
E      +35

test_basic_fixture.py:11: AssertionError</failure></testcase><testcase classname="test_basic_fixture" file="test_basic_fixture.py" line="12" name="test_comparewithBB" time="0.002"></testcase><testcase classname="test_basic_fixture" file="test_basic_fixture.py" line="16" name="test_comparewithCC" time="0.003"><failure message="AssertionError: cc and zz comparison failed
assert 45 == 35
  -45
  +35">supply_AA_BB_CC = [25, 35, 45]

    def test_comparewithCC(supply_AA_BB_CC):
    	zz=35
&gt;   	assert supply_AA_BB_CC[2]==zz,&quot;cc and zz comparison failed&quot;
E    AssertionError: cc and zz comparison failed
E    assert 45 == 35
E      -45
E      +35

test_basic_fixture.py:19: AssertionError</failure></testcase><testcase classname="test_sample1" file="test_sample1.py" line="1" name="test_file1_method1" time="0.002"><failure message="AssertionError: test failed
assert 5 == 6
  -5
  +6">def test_file1_method1():
    	x=5
    	y=6
    	assert x+1 == y,&quot;test failed&quot;
&gt;   	assert x == y,&quot;test failed&quot;
E    AssertionError: test failed
E    assert 5 == 6
E      -5
E      +6

test_sample1.py:6: AssertionError</failure></testcase><testcase classname="test_sample1" file="test_sample1.py" line="6" name="test_file1_method2" time="0.000"></testcase><testcase classname="test_sample1" file="test_sample1.py" line="11" name="test_file1_method3" time="0.002"></testcase><testcase classname="pruebas_rest.test_list_user" file="pruebas_rest\test_list_user.py" line="3" name="test_list_valid_user[1-George]" time="0.105"></testcase><testcase classname="pruebas_rest.test_list_user" file="pruebas_rest\test_list_user.py" line="3" name="test_list_valid_user[2-Janet]" time="0.062"></testcase><testcase classname="pruebas_rest.test_list_user" file="pruebas_rest\test_list_user.py" line="12" name="test_list_invaliduser" time="0.584"></testcase><testcase classname="pruebas_rest.test_login_user" file="pruebas_rest\test_login_user.py" line="3" name="test_login_valid" time="0.549"><failure message="AssertionError: {&quot;error&quot;:&quot;user not found&quot;}
assert 400 == 200
  -400
  +200">supply_url = &apos;https://reqres.in/api&apos;

    def test_login_valid(supply_url):
    	url = supply_url + &quot;/login/&quot;
    	data = {&apos;email&apos;:&apos;test@test.com&apos;,&apos;password&apos;:&apos;something&apos;}
    	resp = requests.post(url, data=data)
    	j = json.loads(resp.text)
&gt;   	assert resp.status_code == 200, resp.text
E    AssertionError: {&quot;error&quot;:&quot;user not found&quot;}
E    assert 400 == 200
E      -400
E      +200

pruebas_rest\test_login_user.py:9: AssertionError</failure></testcase><testcase classname="pruebas_rest.test_login_user" file="pruebas_rest\test_login_user.py" line="11" name="test_login_no_password" time="0.520"></testcase><testcase classname="pruebas_rest.test_login_user" file="pruebas_rest\test_login_user.py" line="19" name="test_login_no_email" time="0.563"></testcase></testsuite></testsuites>